Workbook

Sheet Insights
A1: Season results log: insights
A2: Every figure is a live formula over the 'Seasons' sheet, so it updates as new seasons are added.
A4: Seasons logged | B4: =COUNTA(Seasons!$A:$A)-1
A5: Average final position | B5: =IFERROR(AVERAGE(Seasons!$F:$F),"")
A6: Titles won | B6: =COUNTIF(Seasons!$G:$G,"Yes")
A7: Average points | B7: =IFERROR(AVERAGE(Seasons!$H:$H),"")
A8: Average goals scored / against | B8: =IFERROR(ROUND(AVERAGE(Seasons!$M:$M),1)&" / "&ROUND(AVERAGE(Seasons!$N:$N),1),"")
A10: By main style of play
A11: Main style of play | B11: Seasons | C11: Avg points | D11: Avg position | E11: Best finish | F11: Titles | G11: Avg GF | H11: Avg GA
A12: Balanced | B12: =COUNTIF(Seasons!$S:$S,$A12) | C12: =IFERROR(ROUND(AVERAGEIF(Seasons!$S:$S,$A12,Seasons!$H:$H),1),"") | D12: =IFERROR(ROUND(AVERAGEIF(Seasons!$S:$S,$A12,Seasons!$F:$F),1),"") | E12: =IF(B12=0,"",_xlfn.MINIFS(Seasons!$F:$F,Seasons!$S:$S,$A12)) | F12: =COUNTIFS(Seasons!$S:$S,$A12,Seasons!$G:$G,"Yes") | G12: =IFERROR(ROUND(AVERAGEIF(Seasons!$S:$S,$A12,Seasons!$M:$M),1),"") | H12: =IFERROR(ROUND(AVERAGEIF(Seasons!$S:$S,$A12,Seasons!$N:$N),1),"")
A13: Gegenpress | B13: =COUNTIF(Seasons!$S:$S,$A13) | C13: =IFERROR(ROUND(AVERAGEIF(Seasons!$S:$S,$A13,Seasons!$H:$H),1),"") | D13: =IFERROR(ROUND(AVERAGEIF(Seasons!$S:$S,$A13,Seasons!$F:$F),1),"") | E13: =IF(B13=0,"",_xlfn.MINIFS(Seasons!$F:$F,Seasons!$S:$S,$A13)) | F13: =COUNTIFS(Seasons!$S:$S,$A13,Seasons!$G:$G,"Yes") | G13: =IFERROR(ROUND(AVERAGEIF(Seasons!$S:$S,$A13,Seasons!$M:$M),1),"") | H13: =IFERROR(ROUND(AVERAGEIF(Seasons!$S:$S,$A13,Seasons!$N:$N),1),"")
A14: Tiki-taka | B14: =COUNTIF(Seasons!$S:$S,$A14) | C14: =IFERROR(ROUND(AVERAGEIF(Seasons!$S:$S,$A14,Seasons!$H:$H),1),"") | D14: =IFERROR(ROUND(AVERAGEIF(Seasons!$S:$S,$A14,Seasons!$F:$F),1),"") | E14: =IF(B14=0,"",_xlfn.MINIFS(Seasons!$F:$F,Seasons!$S:$S,$A14)) | F14: =COUNTIFS(Seasons!$S:$S,$A14,Seasons!$G:$G,"Yes") | G14: =IFERROR(ROUND(AVERAGEIF(Seasons!$S:$S,$A14,Seasons!$M:$M),1),"") | H14: =IFERROR(ROUND(AVERAGEIF(Seasons!$S:$S,$A14,Seasons!$N:$N),1),"")
A15: Catenaccio | B15: =COUNTIF(Seasons!$S:$S,$A15) | C15: =IFERROR(ROUND(AVERAGEIF(Seasons!$S:$S,$A15,Seasons!$H:$H),1),"") | D15: =IFERROR(ROUND(AVERAGEIF(Seasons!$S:$S,$A15,Seasons!$F:$F),1),"") | E15: =IF(B15=0,"",_xlfn.MINIFS(Seasons!$F:$F,Seasons!$S:$S,$A15)) | F15: =COUNTIFS(Seasons!$S:$S,$A15,Seasons!$G:$G,"Yes") | G15: =IFERROR(ROUND(AVERAGEIF(Seasons!$S:$S,$A15,Seasons!$M:$M),1),"") | H15: =IFERROR(ROUND(AVERAGEIF(Seasons!$S:$S,$A15,Seasons!$N:$N),1),"")
A16: Counter-attack | B16: =COUNTIF(Seasons!$S:$S,$A16) | C16: =IFERROR(ROUND(AVERAGEIF(Seasons!$S:$S,$A16,Seasons!$H:$H),1),"") | D16: =IFERROR(ROUND(AVERAGEIF(Seasons!$S:$S,$A16,Seasons!$F:$F),1),"") | E16: =IF(B16=0,"",_xlfn.MINIFS(Seasons!$F:$F,Seasons!$S:$S,$A16)) | F16: =COUNTIFS(Seasons!$S:$S,$A16,Seasons!$G:$G,"Yes") | G16: =IFERROR(ROUND(AVERAGEIF(Seasons!$S:$S,$A16,Seasons!$M:$M),1),"") | H16: =IFERROR(ROUND(AVERAGEIF(Seasons!$S:$S,$A16,Seasons!$N:$N),1),"")
A18: By main formation
A19: Main formation | B19: Seasons | C19: Avg points | D19: Avg position | E19: Best finish | F19: Titles | G19: Avg GF | H19: Avg GA
A20: 4-4-2 | B20: =COUNTIF(Seasons!$R:$R,$A20) | C20: =IFERROR(ROUND(AVERAGEIF(Seasons!$R:$R,$A20,Seasons!$H:$H),1),"") | D20: =IFERROR(ROUND(AVERAGEIF(Seasons!$R:$R,$A20,Seasons!$F:$F),1),"") | E20: =IF(B20=0,"",_xlfn.MINIFS(Seasons!$F:$F,Seasons!$R:$R,$A20)) | F20: =COUNTIFS(Seasons!$R:$R,$A20,Seasons!$G:$G,"Yes") | G20: =IFERROR(ROUND(AVERAGEIF(Seasons!$R:$R,$A20,Seasons!$M:$M),1),"") | H20: =IFERROR(ROUND(AVERAGEIF(Seasons!$R:$R,$A20,Seasons!$N:$N),1),"")
A21: 4-3-3 | B21: =COUNTIF(Seasons!$R:$R,$A21) | C21: =IFERROR(ROUND(AVERAGEIF(Seasons!$R:$R,$A21,Seasons!$H:$H),1),"") | D21: =IFERROR(ROUND(AVERAGEIF(Seasons!$R:$R,$A21,Seasons!$F:$F),1),"") | E21: =IF(B21=0,"",_xlfn.MINIFS(Seasons!$F:$F,Seasons!$R:$R,$A21)) | F21: =COUNTIFS(Seasons!$R:$R,$A21,Seasons!$G:$G,"Yes") | G21: =IFERROR(ROUND(AVERAGEIF(Seasons!$R:$R,$A21,Seasons!$M:$M),1),"") | H21: =IFERROR(ROUND(AVERAGEIF(Seasons!$R:$R,$A21,Seasons!$N:$N),1),"")
A22: 4-2-3-1 | B22: =COUNTIF(Seasons!$R:$R,$A22) | C22: =IFERROR(ROUND(AVERAGEIF(Seasons!$R:$R,$A22,Seasons!$H:$H),1),"") | D22: =IFERROR(ROUND(AVERAGEIF(Seasons!$R:$R,$A22,Seasons!$F:$F),1),"") | E22: =IF(B22=0,"",_xlfn.MINIFS(Seasons!$F:$F,Seasons!$R:$R,$A22)) | F22: =COUNTIFS(Seasons!$R:$R,$A22,Seasons!$G:$G,"Yes") | G22: =IFERROR(ROUND(AVERAGEIF(Seasons!$R:$R,$A22,Seasons!$M:$M),1),"") | H22: =IFERROR(ROUND(AVERAGEIF(Seasons!$R:$R,$A22,Seasons!$N:$N),1),"")
A23: 4-1-3-2 | B23: =COUNTIF(Seasons!$R:$R,$A23) | C23: =IFERROR(ROUND(AVERAGEIF(Seasons!$R:$R,$A23,Seasons!$H:$H),1),"") | D23: =IFERROR(ROUND(AVERAGEIF(Seasons!$R:$R,$A23,Seasons!$F:$F),1),"") | E23: =IF(B23=0,"",_xlfn.MINIFS(Seasons!$F:$F,Seasons!$R:$R,$A23)) | F23: =COUNTIFS(Seasons!$R:$R,$A23,Seasons!$G:$G,"Yes") | G23: =IFERROR(ROUND(AVERAGEIF(Seasons!$R:$R,$A23,Seasons!$M:$M),1),"") | H23: =IFERROR(ROUND(AVERAGEIF(Seasons!$R:$R,$A23,Seasons!$N:$N),1),"")
A24: 5-3-2 | B24: =COUNTIF(Seasons!$R:$R,$A24) | C24: =IFERROR(ROUND(AVERAGEIF(Seasons!$R:$R,$A24,Seasons!$H:$H),1),"") | D24: =IFERROR(ROUND(AVERAGEIF(Seasons!$R:$R,$A24,Seasons!$F:$F),1),"") | E24: =IF(B24=0,"",_xlfn.MINIFS(Seasons!$F:$F,Seasons!$R:$R,$A24)) | F24: =COUNTIFS(Seasons!$R:$R,$A24,Seasons!$G:$G,"Yes") | G24: =IFERROR(ROUND(AVERAGEIF(Seasons!$R:$R,$A24,Seasons!$M:$M),1),"") | H24: =IFERROR(ROUND(AVERAGEIF(Seasons!$R:$R,$A24,Seasons!$N:$N),1),"")
A25: 5-2-2-1 | B25: =COUNTIF(Seasons!$R:$R,$A25) | C25: =IFERROR(ROUND(AVERAGEIF(Seasons!$R:$R,$A25,Seasons!$H:$H),1),"") | D25: =IFERROR(ROUND(AVERAGEIF(Seasons!$R:$R,$A25,Seasons!$F:$F),1),"") | E25: =IF(B25=0,"",_xlfn.MINIFS(Seasons!$F:$F,Seasons!$R:$R,$A25)) | F25: =COUNTIFS(Seasons!$R:$R,$A25,Seasons!$G:$G,"Yes") | G25: =IFERROR(ROUND(AVERAGEIF(Seasons!$R:$R,$A25,Seasons!$M:$M),1),"") | H25: =IFERROR(ROUND(AVERAGEIF(Seasons!$R:$R,$A25,Seasons!$N:$N),1),"")
A26: Custom* | B26: =COUNTIF(Seasons!$R:$R,$A26) | C26: =IFERROR(ROUND(AVERAGEIF(Seasons!$R:$R,$A26,Seasons!$H:$H),1),"") | D26: =IFERROR(ROUND(AVERAGEIF(Seasons!$R:$R,$A26,Seasons!$F:$F),1),"") | E26: =IF(B26=0,"",_xlfn.MINIFS(Seasons!$F:$F,Seasons!$R:$R,$A26)) | F26: =COUNTIFS(Seasons!$R:$R,$A26,Seasons!$G:$G,"Yes") | G26: =IFERROR(ROUND(AVERAGEIF(Seasons!$R:$R,$A26,Seasons!$M:$M),1),"") | H26: =IFERROR(ROUND(AVERAGEIF(Seasons!$R:$R,$A26,Seasons!$N:$N),1),"")
A28: By main mentality
A29: Main mentality | B29: Seasons | C29: Avg points | D29: Avg position | E29: Best finish | F29: Titles | G29: Avg GF | H29: Avg GA
A30: Very Defensive | B30: =COUNTIF(Seasons!$V:$V,$A30) | C30: =IFERROR(ROUND(AVERAGEIF(Seasons!$V:$V,$A30,Seasons!$H:$H),1),"") | D30: =IFERROR(ROUND(AVERAGEIF(Seasons!$V:$V,$A30,Seasons!$F:$F),1),"") | E30: =IF(B30=0,"",_xlfn.MINIFS(Seasons!$F:$F,Seasons!$V:$V,$A30)) | F30: =COUNTIFS(Seasons!$V:$V,$A30,Seasons!$G:$G,"Yes") | G30: =IFERROR(ROUND(AVERAGEIF(Seasons!$V:$V,$A30,Seasons!$M:$M),1),"") | H30: =IFERROR(ROUND(AVERAGEIF(Seasons!$V:$V,$A30,Seasons!$N:$N),1),"")
A31: Defensive | B31: =COUNTIF(Seasons!$V:$V,$A31) | C31: =IFERROR(ROUND(AVERAGEIF(Seasons!$V:$V,$A31,Seasons!$H:$H),1),"") | D31: =IFERROR(ROUND(AVERAGEIF(Seasons!$V:$V,$A31,Seasons!$F:$F),1),"") | E31: =IF(B31=0,"",_xlfn.MINIFS(Seasons!$F:$F,Seasons!$V:$V,$A31)) | F31: =COUNTIFS(Seasons!$V:$V,$A31,Seasons!$G:$G,"Yes") | G31: =IFERROR(ROUND(AVERAGEIF(Seasons!$V:$V,$A31,Seasons!$M:$M),1),"") | H31: =IFERROR(ROUND(AVERAGEIF(Seasons!$V:$V,$A31,Seasons!$N:$N),1),"")
A32: Balanced | B32: =COUNTIF(Seasons!$V:$V,$A32) | C32: =IFERROR(ROUND(AVERAGEIF(Seasons!$V:$V,$A32,Seasons!$H:$H),1),"") | D32: =IFERROR(ROUND(AVERAGEIF(Seasons!$V:$V,$A32,Seasons!$F:$F),1),"") | E32: =IF(B32=0,"",_xlfn.MINIFS(Seasons!$F:$F,Seasons!$V:$V,$A32)) | F32: =COUNTIFS(Seasons!$V:$V,$A32,Seasons!$G:$G,"Yes") | G32: =IFERROR(ROUND(AVERAGEIF(Seasons!$V:$V,$A32,Seasons!$M:$M),1),"") | H32: =IFERROR(ROUND(AVERAGEIF(Seasons!$V:$V,$A32,Seasons!$N:$N),1),"")
A33: Attacking | B33: =COUNTIF(Seasons!$V:$V,$A33) | C33: =IFERROR(ROUND(AVERAGEIF(Seasons!$V:$V,$A33,Seasons!$H:$H),1),"") | D33: =IFERROR(ROUND(AVERAGEIF(Seasons!$V:$V,$A33,Seasons!$F:$F),1),"") | E33: =IF(B33=0,"",_xlfn.MINIFS(Seasons!$F:$F,Seasons!$V:$V,$A33)) | F33: =COUNTIFS(Seasons!$V:$V,$A33,Seasons!$G:$G,"Yes") | G33: =IFERROR(ROUND(AVERAGEIF(Seasons!$V:$V,$A33,Seasons!$M:$M),1),"") | H33: =IFERROR(ROUND(AVERAGEIF(Seasons!$V:$V,$A33,Seasons!$N:$N),1),"")
A34: Very Attacking | B34: =COUNTIF(Seasons!$V:$V,$A34) | C34: =IFERROR(ROUND(AVERAGEIF(Seasons!$V:$V,$A34,Seasons!$H:$H),1),"") | D34: =IFERROR(ROUND(AVERAGEIF(Seasons!$V:$V,$A34,Seasons!$F:$F),1),"") | E34: =IF(B34=0,"",_xlfn.MINIFS(Seasons!$F:$F,Seasons!$V:$V,$A34)) | F34: =COUNTIFS(Seasons!$V:$V,$A34,Seasons!$G:$G,"Yes") | G34: =IFERROR(ROUND(AVERAGEIF(Seasons!$V:$V,$A34,Seasons!$M:$M),1),"") | H34: =IFERROR(ROUND(AVERAGEIF(Seasons!$V:$V,$A34,Seasons!$N:$N),1),"")
A36: By main tempo
A37: Main tempo | B37: Seasons | C37: Avg points | D37: Avg position | E37: Best finish | F37: Titles | G37: Avg GF | H37: Avg GA
A38: Slow | B38: =COUNTIF(Seasons!$W:$W,$A38) | C38: =IFERROR(ROUND(AVERAGEIF(Seasons!$W:$W,$A38,Seasons!$H:$H),1),"") | D38: =IFERROR(ROUND(AVERAGEIF(Seasons!$W:$W,$A38,Seasons!$F:$F),1),"") | E38: =IF(B38=0,"",_xlfn.MINIFS(Seasons!$F:$F,Seasons!$W:$W,$A38)) | F38: =COUNTIFS(Seasons!$W:$W,$A38,Seasons!$G:$G,"Yes") | G38: =IFERROR(ROUND(AVERAGEIF(Seasons!$W:$W,$A38,Seasons!$M:$M),1),"") | H38: =IFERROR(ROUND(AVERAGEIF(Seasons!$W:$W,$A38,Seasons!$N:$N),1),"")
A39: Normal | B39: =COUNTIF(Seasons!$W:$W,$A39) | C39: =IFERROR(ROUND(AVERAGEIF(Seasons!$W:$W,$A39,Seasons!$H:$H),1),"") | D39: =IFERROR(ROUND(AVERAGEIF(Seasons!$W:$W,$A39,Seasons!$F:$F),1),"") | E39: =IF(B39=0,"",_xlfn.MINIFS(Seasons!$F:$F,Seasons!$W:$W,$A39)) | F39: =COUNTIFS(Seasons!$W:$W,$A39,Seasons!$G:$G,"Yes") | G39: =IFERROR(ROUND(AVERAGEIF(Seasons!$W:$W,$A39,Seasons!$M:$M),1),"") | H39: =IFERROR(ROUND(AVERAGEIF(Seasons!$W:$W,$A39,Seasons!$N:$N),1),"")
A40: Fast | B40: =COUNTIF(Seasons!$W:$W,$A40) | C40: =IFERROR(ROUND(AVERAGEIF(Seasons!$W:$W,$A40,Seasons!$H:$H),1),"") | D40: =IFERROR(ROUND(AVERAGEIF(Seasons!$W:$W,$A40,Seasons!$F:$F),1),"") | E40: =IF(B40=0,"",_xlfn.MINIFS(Seasons!$F:$F,Seasons!$W:$W,$A40)) | F40: =COUNTIFS(Seasons!$W:$W,$A40,Seasons!$G:$G,"Yes") | G40: =IFERROR(ROUND(AVERAGEIF(Seasons!$W:$W,$A40,Seasons!$M:$M),1),"") | H40: =IFERROR(ROUND(AVERAGEIF(Seasons!$W:$W,$A40,Seasons!$N:$N),1),"")
A42: By main defensive line
A43: Main defensive line | B43: Seasons | C43: Avg points | D43: Avg position | E43: Best finish | F43: Titles | G43: Avg GF | H43: Avg GA
A44: High line | B44: =COUNTIF(Seasons!$X:$X,$A44) | C44: =IFERROR(ROUND(AVERAGEIF(Seasons!$X:$X,$A44,Seasons!$H:$H),1),"") | D44: =IFERROR(ROUND(AVERAGEIF(Seasons!$X:$X,$A44,Seasons!$F:$F),1),"") | E44: =IF(B44=0,"",_xlfn.MINIFS(Seasons!$F:$F,Seasons!$X:$X,$A44)) | F44: =COUNTIFS(Seasons!$X:$X,$A44,Seasons!$G:$G,"Yes") | G44: =IFERROR(ROUND(AVERAGEIF(Seasons!$X:$X,$A44,Seasons!$M:$M),1),"") | H44: =IFERROR(ROUND(AVERAGEIF(Seasons!$X:$X,$A44,Seasons!$N:$N),1),"")
A45: Medium-block | B45: =COUNTIF(Seasons!$X:$X,$A45) | C45: =IFERROR(ROUND(AVERAGEIF(Seasons!$X:$X,$A45,Seasons!$H:$H),1),"") | D45: =IFERROR(ROUND(AVERAGEIF(Seasons!$X:$X,$A45,Seasons!$F:$F),1),"") | E45: =IF(B45=0,"",_xlfn.MINIFS(Seasons!$F:$F,Seasons!$X:$X,$A45)) | F45: =COUNTIFS(Seasons!$X:$X,$A45,Seasons!$G:$G,"Yes") | G45: =IFERROR(ROUND(AVERAGEIF(Seasons!$X:$X,$A45,Seasons!$M:$M),1),"") | H45: =IFERROR(ROUND(AVERAGEIF(Seasons!$X:$X,$A45,Seasons!$N:$N),1),"")
A46: Low defensive line | B46: =COUNTIF(Seasons!$X:$X,$A46) | C46: =IFERROR(ROUND(AVERAGEIF(Seasons!$X:$X,$A46,Seasons!$H:$H),1),"") | D46: =IFERROR(ROUND(AVERAGEIF(Seasons!$X:$X,$A46,Seasons!$F:$F),1),"") | E46: =IF(B46=0,"",_xlfn.MINIFS(Seasons!$F:$F,Seasons!$X:$X,$A46)) | F46: =COUNTIFS(Seasons!$X:$X,$A46,Seasons!$G:$G,"Yes") | G46: =IFERROR(ROUND(AVERAGEIF(Seasons!$X:$X,$A46,Seasons!$M:$M),1),"") | H46: =IFERROR(ROUND(AVERAGEIF(Seasons!$X:$X,$A46,Seasons!$N:$N),1),"")
...

Sheet Seasons
A1: Season ID | B1: Finished (UTC) | C1: Player session | D1: Manager | E1: Club | F1: Final position | G1: Champion | H1: Pts | I1: P | J1: W | K1: D | L1: L | M1: GF | N1: GA | O1: GD | P1: Expected rank (pre-season) | Q1: Places vs expectation | R1: Main formation | S1: Main style of play | T1: Style: matches used | U1: Avg squad fit % | V1: Main mentality | W1: Main tempo | X1: Main defensive line | Y1: Main pressing | Z1: Main passing | AA1: Main defensive stance | AB1: Main attacking preference | AC1: Avg xG for | AD1: Avg xG against | AE1: Avg possession % | AF1: Yellow cards | AG1: Red cards | AH1: Top scorer (club) | AI1: Top scorer goals | AJ1: Best player (avg rating) | AK1: Best player rating | AL1: Tactic changes during season
A2: 20261017-205523-3fa178c6 | B2: 2026-10-17 20:55:23 | C2: 3fa178c6 | E2: Benfica | F2: 2 | G2: No | H2: 71 | I2: 34 | J2: 21 | K2: 8 | L2: 5 | M2: 64 | N2: 35 | O2: 29 | P2: 2.53 | Q2: 1 | R2: 5-2-2-1 | S2: Balanced | T2: 34 | U2: 89.6 | V2: Balanced | W2: Normal | X2: Medium-block | Y2: Balanced | Z2: Balanced | AA2: Compact | AB2: Balanced | AC2: 1.93 | AD2: 1.09 | AE2: 53 | AF2: 46 | AG2: 2 | AH2: V. Pavlidis | AI2: 18 | AJ2: G. Prestianni | AK2: 7.37 | AL2: 0

Sheet Matches
A1: Season ID | B1: Club | C1: Matchday | D1: Venue | E1: Opponent | F1: Result | G1: GF | H1: GA | I1: Score | J1: Formation | K1: Mentality | L1: Tempo | M1: Defensive line | N1: Pressing | O1: Passing | P1: Defensive stance | Q1: Attacking preference | R1: Type of play | S1: Squad fit % | T1: xG for | U1: xG against | V1: Possession % | W1: Yellow cards | X1: Red cards | Y1: Club scorers
A2: 20261017-205523-3fa178c6 | B2: Benfica | C2: 1 | D2: Home | E2: Estoril | F2: W | G2: 1 | H2: 0 | I2: 1-0 | J2: 5-2-2-1 | K2: Balanced | L2: Normal | M2: Medium-block | N2: Balanced | O2: Balanced | P2: Compact | Q2: Balanced | R2: Balanced | S2: 89.5 | T2: 1.92 | U2: 0.68 | V2: 54 | W2: 2 | X2: 0 | Y2: V. Pavlidis 25'
A3: 20261017-205523-3fa178c6 | B3: Benfica | C3: 2 | D3: Away | E3: Alverca | F3: D | G3: 2 | H3: 2 | I3: 2-2 | J3: 5-2-2-1 | K3: Balanced | L3: Normal | M3: Medium-block | N3: Balanced | O3: Balanced | P3: Compact | Q3: Balanced | R3: Balanced | S3: 89.5 | T3: 1.77 | U3: 0.86 | V3: 60.2 | W3: 1 | X3: 0 | Y3: F. Aursnes 7', V. Pavlidis 36'
A4: 20261017-205523-3fa178c6 | B4: Benfica | C4: 3 | D4: Away | E4: Sporting CP | F4: L | G4: 1 | H4: 4 | I4: 1-4 | J4: 5-2-2-1 | K4: Balanced | L4: Normal | M4: Medium-block | N4: Balanced | O4: Balanced | P4: Compact | Q4: Balanced | R4: Balanced | S4: 89.5 | T4: 1.32 | U4: 2.22 | V4: 41.5 | W4: 2 | X4: 0 | Y4: G. Prestianni 19'
A5: 20261017-205523-3fa178c6 | B5: Benfica | C5: 4 | D5: Home | E5: Rio Ave | F5: W | G5: 3 | H5: 2 | I5: 3-2 | J5: 5-2-2-1 | K5: Balanced | L5: Normal | M5: Medium-block | N5: Balanced | O5: Balanced | P5: Compact | Q5: Balanced | R5: Balanced | S5: 89.5 | T5: 2.76 | U5: 1.38 | V5: 65.1 | W5: 1 | X5: 0 | Y5: G. Prestianni 9', V. Pavlidis 16', V. Pavlidis 78'
A6: 20261017-205523-3fa178c6 | B6: Benfica | C6: 5 | D6: Away | E6: SC Braga | F6: W | G6: 1 | H6: 0 | I6: 1-0 | J6: 5-2-2-1 | K6: Balanced | L6: Normal | M6: Medium-block | N6: Balanced | O6: Balanced | P6: Compact | Q6: Balanced | R6: Balanced | S6: 89.5 | T6: 1.45 | U6: 1.19 | V6: 59.8 | W6: 2 | X6: 0 | Y6: S. El Karouani 80'
A7: 20261017-205523-3fa178c6 | B7: Benfica | C7: 6 | D7: Home | E7: Estrela Amadora | F7: W | G7: 4 | H7: 0 | I7: 4-0 | J7: 5-2-2-1 | K7: Balanced | L7: Normal | M7: Medium-block | N7: Balanced | O7: Balanced | P7: Compact | Q7: Balanced | R7: Balanced | S7: 89.5 | T7: 1.87 | U7: 0.9 | V7: 55.6 | W7: 2 | X7: 0 | Y7: V. Pavlidis 17', F. Aursnes 31', G. Prestianni 38', João Palhinha 51'
A8: 20261017-205523-3fa178c6 | B8: Benfica | C8: 7 | D8: Away | E8: Arouca | F8: W | G8: 2 | H8: 0 | I8: 2-0 | J8: 5-2-2-1 | K8: Balanced | L8: Normal | M8: Medium-block | N8: Balanced | O8: Balanced | P8: Compact | Q8: Balanced | R8: Balanced | S8: 89.5 | T8: 1.7 | U8: 1.43 | V8: 45.5 | W8: 1 | X8: 0 | Y8: V. Pavlidis 36', S. Dahl 77'
A9: 20261017-205523-3fa178c6 | B9: Benfica | C9: 8 | D9: Home | E9: Casa Pia AC | F9: W | G9: 2 | H9: 0 | I9: 2-0 | J9: 5-2-2-1 | K9: Balanced | L9: Normal | M9: Medium-block | N9: Balanced | O9: Balanced | P9: Compact | Q9: Balanced | R9: Balanced | S9: 89.5 | T9: 1.9 | U9: 0.63 | V9: 67.9 | W9: 3 | X9: 0 | Y9: A. Schjelderup 86', Rafa Silva 89'
A10: 20261017-205523-3fa178c6 | B10: Benfica | C10: 9 | D10: Away | E10: Académico de Viseu F.C. | F10: W | G10: 1 | H10: 0 | I10: 1-0 | J10: 5-2-2-1 | K10: Balanced | L10: Normal | M10: Medium-block | N10: Balanced | O10: Balanced | P10: Compact | Q10: Balanced | R10: Balanced | S10: 89.5 | T10: 1.86 | U10: 0.88 | V10: 73.9 | W10: 2 | X10: 0 | Y10: G. Prestianni 70'
A11: 20261017-205523-3fa178c6 | B11: Benfica | C11: 10 | D11: Home | E11: Nacional | F11: W | G11: 4 | H11: 0 | I11: 4-0 | J11: 5-2-2-1 | K11: Balanced | L11: Normal | M11: Medium-block | N11: Balanced | O11: Balanced | P11: Compact | Q11: Balanced | R11: Balanced | S11: 89.5 | T11: 1.84 | U11: 0.6 | V11: 47.5 | W11: 1 | X11: 0 | Y11: V. Pavlidis 12', G. Prestianni 26', V. Pavlidis 71', V. Pavlidis 80'
A12: 20261017-205523-3fa178c6 | B12: Benfica | C12: 11 | D12: Away | E12: Marítimo | F12: D | G12: 1 | H12: 1 | I12: 1-1 | J12: 5-2-2-1 | K12: Balanced | L12: Normal | M12: Medium-block | N12: Balanced | O12: Balanced | P12: Compact | Q12: Balanced | R12: Balanced | S12: 89.5 | T12: 1.95 | U12: 1.09 | V12: 58.9 | W12: 1 | X12: 0 | Y12: A. Schjelderup 38'
A13: 20261017-205523-3fa178c6 | B13: Benfica | C13: 12 | D13: Away | E13: Santa Clara | F13: D | G13: 1 | H13: 1 | I13: 1-1 | J13: 5-2-2-1 | K13: Balanced | L13: Normal | M13: Medium-block | N13: Balanced | O13: Balanced | P13: Compact | Q13: Balanced | R13: Balanced | S13: 89.5 | T13: 1.56 | U13: 0.89 | V13: 51.3 | W13: 0 | X13: 0 | Y13: João Palhinha 33'
... A17: 20261017-205523-3fa178c6 | B17: Benfica | C17: 16 | D17: Away | E17: Gil Vicente | F17: W | G17: 3 | H17: 1 | I17: 3-1 | J17: 5-2-2-1 | K17: Balanced | L17: Normal | M17: Medium-block | N17: Balanced | O17: Balanced | P17: Compact | Q17: Balanced | R17: Balanced | S17: 89.5 | T17: 1.95 | U17: 1.77 | V17: 48.6 | W17: 0 | X17: 0 | Y17: G. Prestianni 6', A. Schjelderup 34', A. Schjelderup 58'
A18: 20261017-205523-3fa178c6 | B18: Benfica | C18: 17 | D18: Home | E18: Porto | F18: D | G18: 0 | H18: 0 | I18: 0-0 | J18: 5-2-2-1 | K18: Balanced | L18: Normal | M18: Medium-block | N18: Balanced | O18: Balanced | P18: Compact | Q18: Balanced | R18: Balanced | S18: 89.5 | T18: 1.72 | U18: 1.26 | V18: 30.8 | W18: 1 | X18: 0
A19: 20261017-205523-3fa178c6 | B19: Benfica | C19: 18 | D19: Away | E19: Estoril | F19: L | G19: 0 | H19: 1 | I19: 0-1 | J19: 5-2-2-1 | K19: Balanced | L19: Normal | M19: Medium-block | N19: Balanced | O19: Balanced | P19: Compact | Q19: Balanced | R19: Balanced | S19: 89.5 | T19: 1.87 | U19: 1.18 | V19: 61.2 | W19: 2 | X19: 0
A20: 20261017-205523-3fa178c6 | B20: Benfica | C20: 19 | D20: Home | E20: Alverca | F20: W | G20: 2 | H20: 1 | I20: 2-1 | J20: 5-2-2-1 | K20: Balanced | L20: Normal | M20: Medium-block | N20: Balanced | O20: Balanced | P20: Compact | Q20: Balanced | R20: Balanced | S20: 89.5 | T20: 2.81 | U20: 0.84 | V20: 50.2 | W20: 1 | X20: 0 | Y20: A. Schjelderup 48', G. Prestianni 52'
A21: 20261017-205523-3fa178c6 | B21: Benfica | C21: 20 | D21: Home | E21: Sporting CP | F21: W | G21: 1 | H21: 0 | I21: 1-0 | J21: 5-2-2-1 | K21: Balanced | L21: Normal | M21: Medium-block | N21: Balanced | O21: Balanced | P21: Compact | Q21: Balanced | R21: Balanced | S21: 89.5 | T21: 1.83 | U21: 2.11 | V21: 45.3 | W21: 2 | X21: 0 | Y21: F. Aursnes 21'
A22: 20261017-205523-3fa178c6 | B22: Benfica | C22: 21 | D22: Away | E22: Rio Ave | F22: W | G22: 4 | H22: 2 | I22: 4-2 | J22: 5-2-2-1 | K22: Balanced | L22: Normal | M22: Medium-block | N22: Balanced | O22: Balanced | P22: Compact | Q22: Balanced | R22: Balanced | S22: 89.5 | T22: 2.34 | U22: 1.7 | V22: 45.2 | W22: 1 | X22: 0 | Y22: G. Prestianni 36', G. Prestianni 60', Rafa Silva 78', Rafa Silva 83'
A23: 20261017-205523-3fa178c6 | B23: Benfica | C23: 22 | D23: Home | E23: SC Braga | F23: W | G23: 1 | H23: 0 | I23: 1-0 | J23: 5-2-2-1 | K23: Balanced | L23: Normal | M23: Medium-block | N23: Balanced | O23: Balanced | P23: Compact | Q23: Balanced | R23: Balanced | S23: 89.5 | T23: 1.67 | U23: 1.16 | V23: 30.5 | W23: 0 | X23: 0 | Y23: V. Pavlidis 10'
A24: 20261017-205523-3fa178c6 | B24: Benfica | C24: 23 | D24: Away | E24: Estrela Amadora | F24: L | G24: 3 | H24: 4 | I24: 3-4 | J24: 5-2-2-1 | K24: Balanced | L24: Normal | M24: Medium-block | N24: Balanced | O24: Balanced | P24: Compact | Q24: Balanced | R24: Balanced | S24: 89.5 | T24: 1.47 | U24: 1.06 | V24: 62.4 | W24: 2 | X24: 0 | Y24: A. Schjelderup 8', F. Aursnes 25', José Neto 76'
A25: 20261017-205523-3fa178c6 | B25: Benfica | C25: 24 | D25: Home | E25: Arouca | F25: W | G25: 2 | H25: 1 | I25: 2-1 | J25: 5-2-2-1 | K25: Balanced | L25: Normal | M25: Medium-block | N25: Balanced | O25: Balanced | P25: Compact | Q25: Balanced | R25: Balanced | S25: 89.5 | T25: 1.48 | U25: 0.58 | V25: 55.3 | W25: 0 | X25: 1 | Y25: José Neto 78', V. Pavlidis 84'
A26: 20261017-205523-3fa178c6 | B26: Benfica | C26: 25 | D26: Away | E26: Casa Pia AC | F26: W | G26: 2 | H26: 0 | I26: 2-0 | J26: 5-2-2-1 | K26: Balanced | L26: Normal | M26: Medium-block | N26: Balanced | O26: Balanced | P26: Compact | Q26: Balanced | R26: Balanced | S26: 89.9 | T26: 1.68 | U26: 0.8 | V26: 50.4 | W26: 0 | X26: 0 | Y26: V. Pavlidis 14', G. Prestianni 35'
A27: 20261017-205523-3fa178c6 | B27: Benfica | C27: 26 | D27: Home | E27: Académico de Viseu F.C. | F27: W | G27: 2 | H27: 0 | I27: 2-0 | J27: 5-2-2-1 | K27: Balanced | L27: Normal | M27: Medium-block | N27: Balanced | O27: Balanced | P27: Compact | Q27: Balanced | R27: Balanced | S27: 89.9 | T27: 3.16 | U27: 0.95 | V27: 54.3 | W27: 2 | X27: 0 | Y27: V. Pavlidis 73', V. Pavlidis 75'
A28: 20261017-205523-3fa178c6 | B28: Benfica | C28: 27 | D28: Away | E28: Nacional | F28: D | G28: 2 | H28: 2 | I28: 2-2 | J28: 5-2-2-1 | K28: Balanced | L28: Normal | M28: Medium-block | N28: Balanced | O28: Balanced | P28: Compact | Q28: Balanced | R28: Balanced | S28: 89.9 | T28: 1.21 | U28: 0.72 | V28: 56 | W28: 1 | X28: 0 | Y28: E. Barrenechea 19', V. Pavlidis 30'
A29: 20261017-205523-3fa178c6 | B29: Benfica | C29: 28 | D29: Home | E29: Marítimo | F29: W | G29: 4 | H29: 0 | I29: 4-0 | J29: 5-2-2-1 | K29: Balanced | L29: Normal | M29: Medium-block | N29: Balanced | O29: Balanced | P29: Compact | Q29: Balanced | R29: Balanced | S29: 89.5 | T29: 3.31 | U29: 0.66 | V29: 55.1 | W29: 0 | X29: 0 | Y29: G. Prestianni 60', F. Aursnes 64', A. Schjelderup 78', S. El Karouani 82'
A30: 20261017-205523-3fa178c6 | B30: Benfica | C30: 29 | D30: Home | E30: Santa Clara | F30: W | G30: 2 | H30: 0 | I30: 2-0 | J30: 5-2-2-1 | K30: Balanced | L30: Normal | M30: Medium-block | N30: Balanced | O30: Balanced | P30: Compact | Q30: Balanced | R30: Balanced | S30: 89.5 | T30: 2.56 | U30: 0.97 | V30: 50.1 | W30: 3 | X30: 1 | Y30: A. Schjelderup 49', V. Pavlidis 54'
A31: 20261017-205523-3fa178c6 | B31: Benfica | C31: 30 | D31: Away | E31: Famalicão | F31: D | G31: 0 | H31: 0 | I31: 0-0 | J31: 5-2-2-1 | K31: Balanced | L31: Normal | M31: Medium-block | N31: Balanced | O31: Balanced | P31: Compact | Q31: Balanced | R31: Balanced | S31: 89.9 | T31: 1.17 | U31: 0.98 | V31: 58.8 | W31: 2 | X31: 0
A32: 20261017-205523-3fa178c6 | B32: Benfica | C32: 31 | D32: Home | E32: Vitória SC | F32: W | G32: 3 | H32: 2 | I32: 3-2 | J32: 5-2-2-1 | K32: Balanced | L32: Normal | M32: Medium-block | N32: Balanced | O32: Balanced | P32: Compact | Q32: Balanced | R32: Balanced | S32: 89.5 | T32: 1.92 | U32: 1.05 | V32: 52.6 | W32: 0 | X32: 0 | Y32: A. Bah 53', H. Sudakov 67', Rafa Silva 78'
A33: 20261017-205523-3fa178c6 | B33: Benfica | C33: 32 | D33: Away | E33: Moreirense | F33: W | G33: 2 | H33: 1 | I33: 2-1 | J33: 5-2-2-1 | K33: Balanced | L33: Normal | M33: Medium-block | N33: Balanced | O33: Balanced | P33: Compact | Q33: Balanced | R33: Balanced | S33: 89.5 | T33: 2.05 | U33: 1.33 | V33: 51.5 | W33: 3 | X33: 0 | Y33: A. Schjelderup 7', F. Aursnes 84'
A34: 20261017-205523-3fa178c6 | B34: Benfica | C34: 33 | D34: Home | E34: Gil Vicente | F34: L | G34: 0 | H34: 1 | I34: 0-1 | J34: 5-2-2-1 | K34: Balanced | L34: Normal | M34: Medium-block | N34: Balanced | O34: Balanced | P34: Compact | Q34: Balanced | R34: Balanced | S34: 89.5 | T34: 2.81 | U34: 1.04 | V34: 69.7 | W34: 3 | X34: 0
A35: 20261017-205523-3fa178c6 | B35: Benfica | C35: 34 | D35: Away | E35: Porto | F35: L | G35: 2 | H35: 4 | I35: 2-4 | J35: 5-2-2-1 | K35: Balanced | L35: Normal | M35: Medium-block | N35: Balanced | O35: Balanced | P35: Compact | Q35: Balanced | R35: Balanced | S35: 89.5 | T35: 0.89 | U35: 1.14 | V35: 54.8 | W35: 1 | X35: 0 | Y35: V. Pavlidis 9', H. Sudakov 71'

Sheet Scorers
A1: Season ID | B1: Club (user) | C1: Player | D1: Team | E1: Position | F1: Apps | G1: Goals | H1: Assists | I1: Avg rating | J1: Own club?
A2: 20261017-205523-3fa178c6 | B2: Benfica | C2: V. Pavlidis | D2: Benfica | E2: CF | F2: 34 | G2: 18 | H2: 1 | I2: 7.23 | J2: Yes
A3: 20261017-205523-3fa178c6 | B3: Benfica | C3: L. Suárez | D3: Sporting CP | E3: CF | F3: 34 | G3: 17 | H3: 5 | I3: 7.38 | J3: No
A4: 20261017-205523-3fa178c6 | B4: Benfica | C4: M. Kaba | D4: Gil Vicente | E4: CF | F4: 35 | G4: 17 | H4: 5 | I4: 7.09 | J4: No
A5: 20261017-205523-3fa178c6 | B5: Benfica | C5: Gustavo Silva | D5: Vitória SC | E5: CF | F5: 34 | G5: 16 | H5: 3 | I5: 6.98 | J5: No
A6: 20261017-205523-3fa178c6 | B6: Benfica | C6: Geny Catamo | D6: Sporting CP | E6: AM & W | F6: 34 | G6: 15 | H6: 7 | I6: 7.48 | J6: No
A7: 20261017-205523-3fa178c6 | B7: Benfica | C7: Pau Víctor | D7: SC Braga | E7: CF | F7: 34 | G7: 15 | H7: 3 | I7: 7.15 | J7: No
A8: 20261017-205523-3fa178c6 | B8: Benfica | C8: Gil Dias | D8: Famalicão | E8: AM & W | F8: 32 | G8: 15 | H8: 2 | I8: 7.03 | J8: No
A9: 20261017-205523-3fa178c6 | B9: Benfica | C9: G. Prestianni | D9: Benfica | E9: AM & W | F9: 34 | G9: 12 | H9: 6 | I9: 7.37 | J9: Yes
A10: 20261017-205523-3fa178c6 | B10: Benfica | C10: A. Schjelderup | D10: Benfica | E10: AM & W | F10: 34 | G10: 12 | H10: 5 | I10: 7.13 | J10: Yes
A11: 20261017-205523-3fa178c6 | B11: Benfica | C11: Andre Clóvis | D11: Académico de Viseu F.C. | E11: CF | F11: 35 | G11: 12 | H11: 2 | I11: 6.91 | J11: No
A12: 20261017-205523-3fa178c6 | B12: Benfica | C12: F. Aursnes | D12: Benfica | E12: MF | F12: 34 | G12: 6 | H12: 6 | I12: 7.01 | J12: Yes
A13: 20261017-205523-3fa178c6 | B13: Benfica | C13: Rafa Silva | D13: Benfica | E13: AM & W | F13: 22 | G13: 4 | H13: 1 | I13: 6.65 | J13: Yes
... A25: 20261017-205523-3fa178c6 | B25: Benfica | C25: A. Trubin | D25: Benfica | E25: GK | F25: 34 | G25: 0 | H25: 0 | I25: 6.74 | J25: Yes

Sheet Lineups
A1: Season ID | B1: Club (user) | C1: Formation | D1: Slot | E1: Player | F1: Position | G1: Role | H1: Apps | I1: Goals | J1: Assists | K1: Avg rating
A2: 20261017-205523-3fa178c6 | B2: Benfica | C2: 5-2-2-1 | D2: GK | E2: A. Trubin | F2: GK | G2: GK | H2: 34 | I2: 0 | J2: 0 | K2: 6.74
A3: 20261017-205523-3fa178c6 | B3: Benfica | C3: 5-2-2-1 | D3: LCB | E3: C. Lenglet | F3: CB | G3: Balanced | H3: 34 | I3: 0 | J3: 1 | K3: 6.66
A4: 20261017-205523-3fa178c6 | B4: Benfica | C4: 5-2-2-1 | D4: CB | E4: A. Circati | F4: CB | G4: Balanced | H4: 34 | I4: 0 | J4: 0 | K4: 6.59
A5: 20261017-205523-3fa178c6 | B5: Benfica | C5: 5-2-2-1 | D5: RCB | E5: Tomás Araújo | F5: CB | G5: Balanced | H5: 34 | I5: 0 | J5: 3 | K5: 6.81
A6: 20261017-205523-3fa178c6 | B6: Benfica | C6: 5-2-2-1 | D6: LWB | E6: S. El Karouani | F6: FB & WB | G6: Balanced | H6: 34 | I6: 3 | J6: 6 | K6: 6.72
A7: 20261017-205523-3fa178c6 | B7: Benfica | C7: 5-2-2-1 | D7: RWB | E7: A. Bah | F7: FB & WB | G7: Balanced | H7: 34 | I7: 1 | J7: 4 | K7: 7
A8: 20261017-205523-3fa178c6 | B8: Benfica | C8: 5-2-2-1 | D8: LCM | E8: João Palhinha | F8: MF | G8: Balanced | H8: 30 | I8: 2 | J8: 7 | K8: 6.89
A9: 20261017-205523-3fa178c6 | B9: Benfica | C9: 5-2-2-1 | D9: RCM | E9: F. Aursnes | F9: MF | G9: Balanced | H9: 34 | I9: 6 | J9: 6 | K9: 7.01
A10: 20261017-205523-3fa178c6 | B10: Benfica | C10: 5-2-2-1 | D10: LAM | E10: G. Prestianni | F10: AM & W | G10: Balanced | H10: 34 | I10: 12 | J10: 6 | K10: 7.37
A11: 20261017-205523-3fa178c6 | B11: Benfica | C11: 5-2-2-1 | D11: RAM | E11: A. Schjelderup | F11: AM & W | G11: Balanced | H11: 34 | I11: 12 | J11: 5 | K11: 7.13
A12: 20261017-205523-3fa178c6 | B12: Benfica | C12: 5-2-2-1 | D12: ST | E12: V. Pavlidis | F12: CF | G12: Balanced | H12: 34 | I12: 18 | J12: 1 | K12: 7.23

Sheet Final table
A1: Season ID | B1: Pos | C1: Team | D1: P | E1: W | F1: D | G1: L | H1: GF | I1: GA | J1: GD | K1: Pts | L1: User club?
A2: 20261017-205523-3fa178c6 | B2: 1 | C2: Sporting CP | D2: 34 | E2: 23 | F2: 6 | G2: 5 | H2: 68 | I2: 26 | J2: 42 | K2: 75 | L2: No
A3: 20261017-205523-3fa178c6 | B3: 2 | C3: Benfica | D3: 34 | E3: 21 | F3: 8 | G3: 5 | H3: 64 | I3: 35 | J3: 29 | K3: 71 | L3: Yes
A4: 20261017-205523-3fa178c6 | B4: 3 | C4: SC Braga | D4: 34 | E4: 19 | F4: 6 | G4: 9 | H4: 56 | I4: 35 | J4: 21 | K4: 63 | L4: No
A5: 20261017-205523-3fa178c6 | B5: 4 | C5: Porto | D5: 35 | E5: 17 | F5: 10 | G5: 8 | H5: 47 | I5: 32 | J5: 15 | K5: 61 | L5: No
A6: 20261017-205523-3fa178c6 | B6: 5 | C6: Gil Vicente | D6: 35 | E6: 16 | F6: 4 | G6: 15 | H6: 59 | I6: 48 | J6: 11 | K6: 52 | L6: No
A7: 20261017-205523-3fa178c6 | B7: 6 | C7: Famalicão | D7: 34 | E7: 15 | F7: 6 | G7: 13 | H7: 49 | I7: 45 | J7: 4 | K7: 51 | L7: No
A8: 20261017-205523-3fa178c6 | B8: 7 | C8: Santa Clara | D8: 34 | E8: 12 | F8: 12 | G8: 10 | H8: 35 | I8: 32 | J8: 3 | K8: 48 | L8: No
A9: 20261017-205523-3fa178c6 | B9: 8 | C9: Estoril | D9: 35 | E9: 12 | F9: 11 | G9: 12 | H9: 42 | I9: 36 | J9: 6 | K9: 47 | L9: No
A10: 20261017-205523-3fa178c6 | B10: 9 | C10: Estrela Amadora | D10: 34 | E10: 11 | F10: 13 | G10: 10 | H10: 39 | I10: 37 | J10: 2 | K10: 46 | L10: No
A11: 20261017-205523-3fa178c6 | B11: 10 | C11: Arouca | D11: 35 | E11: 12 | F11: 9 | G11: 14 | H11: 32 | I11: 43 | J11: -11 | K11: 45 | L11: No
A12: 20261017-205523-3fa178c6 | B12: 11 | C12: Académico de Viseu F.C. | D12: 35 | E12: 10 | F12: 11 | G12: 14 | H12: 34 | I12: 56 | J12: -22 | K12: 41 | L12: No
A13: 20261017-205523-3fa178c6 | B13: 12 | C13: Alverca | D13: 35 | E13: 10 | F13: 10 | G13: 15 | H13: 33 | I13: 44 | J13: -11 | K13: 40 | L13: No
... A19: 20261017-205523-3fa178c6 | B19: 18 | C19: Moreirense | D19: 35 | E19: 8 | F19: 8 | G19: 19 | H19: 33 | I19: 52 | J19: -19 | K19: 32 | L19: No
